18:04:01 -     INFO - wally           - All info would be stored into /var/wally_results/noninteractive_isela
18:04:01 -     INFO - wally           - Start discover_stage
18:04:01 -     INFO - wally           - Start reuse_vms_stage
18:04:01 -     INFO - wally           - Start log_nodes_statistic_stage
18:04:01 -     INFO - wally           - Found 1 nodes total
18:04:01 -    DEBUG - wally           - Found 1 nodes with role testnode
18:04:01 -     INFO - wally           - Start save_nodes_stage
18:04:01 -     INFO - wally           - Start connect_stage
18:04:01 -     INFO - wally           - Connecting to nodes
18:04:01 -     INFO - wally           - All nodes connected successfully
18:04:01 -     INFO - wally           - Start run_tests_stage
18:04:01 -    DEBUG - wally           - Run preparation
18:04:02 -    ERROR - wally           - File data check is failed - Traceback (most recent call last):
  File "<string>", line 1, in <module>
IOError: [Errno 21] Is a directory: '/ssd'
d41d8cd98f00b204e9800998ecf8427e  -

18:04:02 -     INFO - wally           - Prefilling file /ssd
18:04:02 -    DEBUG - wally           - SSH:138.219.228.43:22 Exec 'sudo fio --name=xxx --filename=/ssd --direct=1 --bs=4m --size=20480m --rw=write'
18:04:03 -    ERROR - wally           - XXXX
Traceback (most recent call last):
  File "/usr/local/lib/python2.7/dist-packages/wally/suits/io/fio.py", line 669, in pre_run_th
    self.prefill_test_files(rossh, files, force)
  File "/usr/local/lib/python2.7/dist-packages/wally/suits/io/fio.py", line 554, in prefill_test_files
    rossh(cmd, timeout=curr_sz)
  File "/usr/local/lib/python2.7/dist-packages/wally/suits/itest.py", line 204, in closure
    **kwargs)
  File "/usr/local/lib/python2.7/dist-packages/wally/ssh_utils.py", line 543, in run_over_ssh
    raise OSError(templ.format(node, cmd, code, output))
OSError: SSH:138.219.228.43:22 Cmd 'sudo fio --name=xxx --filename=/ssd --direct=1 --bs=4m --size=20480m --rw=write' failed with code 1. Output: xxx: (g=0): rw=write, bs=4M-4M/4M-4M/4M-4M, ioengine=sync, iodepth=1
fio-2.2.8
Starting 1 process
fio: pid=0, err=21/file:filesetup.c:63, func=unlink, error=Is a directory
xxx: Laying out IO file(s) (1 file(s) / 20480MB)


Run status group 0 (all jobs):

18:04:03 -    ERROR - wally           - During run_tests_stage
Traceback (most recent call last):
  File "/usr/local/lib/python2.7/dist-packages/wally/main.py", line 124, in log_stage
    yield
  File "/usr/local/lib/python2.7/dist-packages/wally/main.py", line 276, in main
    stage(cfg, ctx)
  File "/usr/local/lib/python2.7/dist-packages/wally/run_test.py", line 481, in run_tests_stage
    for tp, res in run_tests(cfg, test_group, ctx.nodes):
  File "/usr/local/lib/python2.7/dist-packages/wally/run_test.py", line 242, in run_tests
    res = test_cls(test_cfg).run()
  File "/usr/local/lib/python2.7/dist-packages/wally/suits/io/fio.py", line 688, in run
    self.pre_run()
  File "/usr/local/lib/python2.7/dist-packages/wally/suits/io/fio.py", line 643, in pre_run
    list(pool.map(fc, self.config.nodes))
  File "/usr/local/lib/python2.7/dist-packages/concurrent/futures/_base.py", line 581, in result_iterator
    yield future.result()
  File "/usr/local/lib/python2.7/dist-packages/concurrent/futures/_base.py", line 405, in result
    return self.__get_result()
  File "/usr/local/lib/python2.7/dist-packages/concurrent/futures/thread.py", line 55, in run
    result = self.fn(*self.args, **self.kwargs)
  File "/usr/local/lib/python2.7/dist-packages/wally/suits/io/fio.py", line 669, in pre_run_th
    self.prefill_test_files(rossh, files, force)
  File "/usr/local/lib/python2.7/dist-packages/wally/suits/io/fio.py", line 554, in prefill_test_files
    rossh(cmd, timeout=curr_sz)
  File "/usr/local/lib/python2.7/dist-packages/wally/suits/itest.py", line 204, in closure
    **kwargs)
  File "/usr/local/lib/python2.7/dist-packages/wally/ssh_utils.py", line 543, in run_over_ssh
    raise OSError(templ.format(node, cmd, code, output))
OSError: SSH:138.219.228.43:22 Cmd 'sudo fio --name=xxx --filename=/ssd --direct=1 --bs=4m --size=20480m --rw=write' failed with code 1. Output: xxx: (g=0): rw=write, bs=4M-4M/4M-4M/4M-4M, ioengine=sync, iodepth=1
fio-2.2.8
Starting 1 process
fio: pid=0, err=21/file:filesetup.c:63, func=unlink, error=Is a directory
xxx: Laying out IO file(s) (1 file(s) / 20480MB)


Run status group 0 (all jobs):

18:04:03 -     INFO - wally           - Start disconnect_stage
18:04:03 -    DEBUG - wally           - Start utils.cleanup
18:04:03 -     INFO - wally           - All info stored into /var/wally_results/noninteractive_isela
18:04:03 -    ERROR - wally           - Tests are failed. See detailed error above
