10:37:11 -     INFO - wally           - All info would be stored into /home/mosorio/wally/wally_results/pretty_bobcat
10:37:11 -     INFO - wally           - Start discover_stage
10:37:11 -     INFO - wally           - Start reuse_vms_stage
10:37:11 -     INFO - wally           - Start log_nodes_statistic_stage
10:37:11 -     INFO - wally           - Found 1 nodes total
10:37:11 -    DEBUG - wally           - Found 1 nodes with role testnode
10:37:11 -     INFO - wally           - Start save_nodes_stage
10:37:11 -     INFO - wally           - Start connect_stage
10:37:11 -     INFO - wally           - Connecting to nodes
10:37:12 -     INFO - wally           - All nodes connected successfully
10:37:12 -     INFO - wally           - Start run_tests_stage
10:37:12 -    DEBUG - wally           - Run preparation
10:37:14 -    DEBUG - wally           - prefill is skipped
10:37:14 -     INFO - wally           - Entire test should takes aroud: 0:16:30 and finished at 10:53:44
10:37:14 -     INFO - wally           - Will run hdd_rwx4kth1 test
10:37:14 -     INFO - wally           - Test should takes about 0:02:30. Should finish at 10:39:44, will wait at most till 10:44:44
10:37:14 -    DEBUG - wally           - SSH:138.219.231.195:2121 Exec 'screen -S test -d -m sudo bash /tmp/wally/pretty_bobcat/io/cmd.sh'
10:39:48 -    DEBUG - wally           - Test on node 138.219.231.195_2121 is finished
10:39:48 -    ERROR - wally           - During run_tests_stage
Traceback (most recent call last):
  File "wally/main.py", line 125, in log_stage
    yield
  File "wally/main.py", line 277, in main
    stage(cfg, ctx)
  File "wally/run_test.py", line 481, in run_tests_stage
    for tp, res in run_tests(cfg, test_group, ctx.nodes):
  File "wally/run_test.py", line 242, in run_tests
    res = test_cls(test_cfg).run()
  File "wally/suits/io/fio.py", line 765, in run
    res = load_test_results(self.config.log_directory, pos)
  File "wally/suits/io/fio.py", line 131, in load_test_results
    ts = load_sys_log_file(ftype, os.path.join(folder, fname))
  File "wally/suits/io/fio.py", line 89, in load_sys_log_file
    return TimeSeriesValue(vals)
  File "wally/suits/itest.py", line 116, in __init__
    assert len(data) > 0
AssertionError
10:39:48 -     INFO - wally           - Start disconnect_stage
10:39:49 -    DEBUG - wally           - Start utils.cleanup
10:39:49 -     INFO - wally           - All info stored into /home/mosorio/wally/wally_results/pretty_bobcat
10:39:49 -    ERROR - wally           - Tests are failed. See detailed error above
