10:25:03 -     INFO - wally           - All info would be stored into /home/mosorio/wally/wally_results/free_mako
10:25:03 -     INFO - wally           - Start discover_stage
10:25:03 -     INFO - wally           - Start reuse_vms_stage
10:25:03 -     INFO - wally           - Start log_nodes_statistic_stage
10:25:03 -     INFO - wally           - Found 1 nodes total
10:25:03 -    DEBUG - wally           - Found 1 nodes with role testnode
10:25:03 -     INFO - wally           - Start save_nodes_stage
10:25:03 -     INFO - wally           - Start connect_stage
10:25:03 -     INFO - wally           - Connecting to nodes
10:25:04 -     INFO - wally           - All nodes connected successfully
10:25:04 -     INFO - wally           - Start run_tests_stage
10:25:04 -    DEBUG - wally           - Run preparation
10:25:04 -     INFO - wally           - Prefilling file /dev/rbd0
10:25:04 -    DEBUG - wally           - SSH:172.19.1.1:22 Exec 'sudo fio --name=xxx --filename=/dev/rbd0 --direct=1 --bs=4m --size=20480m --rw=write'
10:25:05 -    ERROR - wally           - XXXX
Traceback (most recent call last):
  File "wally/suits/io/fio.py", line 668, in pre_run_th
    self.prefill_test_files(rossh, files, force)
  File "wally/suits/io/fio.py", line 554, in prefill_test_files
    rossh(cmd, timeout=curr_sz)
  File "wally/suits/itest.py", line 204, in closure
    **kwargs)
  File "wally/ssh_utils.py", line 543, in run_over_ssh
    raise OSError(templ.format(node, cmd, code, output))
OSError: SSH:172.19.1.1:22 Cmd 'sudo fio --name=xxx --filename=/dev/rbd0 --direct=1 --bs=4m --size=20480m --rw=write' failed with code 1. Output: xxx: (g=0): rw=write, bs=4M-4M/4M-4M/4M-4M, ioengine=sync, iodepth=1
fio-2.2.10
Starting 1 process
fio: looks like your file system does not support direct=1/buffered=0
fio: destination does not support O_DIRECT


Run status group 0 (all jobs):

10:25:05 -    ERROR - wally           - During run_tests_stage
Traceback (most recent call last):
  File "wally/main.py", line 125, in log_stage
    yield
  File "wally/main.py", line 277, in main
    stage(cfg, ctx)
  File "wally/run_test.py", line 481, in run_tests_stage
    for tp, res in run_tests(cfg, test_group, ctx.nodes):
  File "wally/run_test.py", line 242, in run_tests
    res = test_cls(test_cfg).run()
  File "wally/suits/io/fio.py", line 687, in run
    self.pre_run()
  File "wally/suits/io/fio.py", line 642, in pre_run
    list(pool.map(fc, self.config.nodes))
  File "/home/mosorio/wally_env/local/lib/python2.7/site-packages/concurrent/futures/_base.py", line 581, in result_iterator
    yield future.result()
  File "/home/mosorio/wally_env/local/lib/python2.7/site-packages/concurrent/futures/_base.py", line 405, in result
    return self.__get_result()
  File "/home/mosorio/wally_env/local/lib/python2.7/site-packages/concurrent/futures/thread.py", line 55, in run
    result = self.fn(*self.args, **self.kwargs)
  File "wally/suits/io/fio.py", line 668, in pre_run_th
    self.prefill_test_files(rossh, files, force)
  File "wally/suits/io/fio.py", line 554, in prefill_test_files
    rossh(cmd, timeout=curr_sz)
  File "wally/suits/itest.py", line 204, in closure
    **kwargs)
  File "wally/ssh_utils.py", line 543, in run_over_ssh
    raise OSError(templ.format(node, cmd, code, output))
OSError: SSH:172.19.1.1:22 Cmd 'sudo fio --name=xxx --filename=/dev/rbd0 --direct=1 --bs=4m --size=20480m --rw=write' failed with code 1. Output: xxx: (g=0): rw=write, bs=4M-4M/4M-4M/4M-4M, ioengine=sync, iodepth=1
fio-2.2.10
Starting 1 process
fio: looks like your file system does not support direct=1/buffered=0
fio: destination does not support O_DIRECT


Run status group 0 (all jobs):

10:25:05 -     INFO - wally           - Start disconnect_stage
10:25:05 -    DEBUG - wally           - Start utils.cleanup
10:25:05 -     INFO - wally           - All info stored into /home/mosorio/wally/wally_results/free_mako
10:25:05 -    ERROR - wally           - Tests are failed. See detailed error above
18:20:29 -     INFO - wally           - All info would be stored into /home/mosorio/wally/wally_results/free_mako
18:20:29 -     INFO - wally           - Start load_data_from_path_stage
18:20:29 -    ERROR - wally           - During load_data_from_path_stage
Traceback (most recent call last):
  File "wally/main.py", line 125, in log_stage
    yield
  File "wally/main.py", line 277, in main
    stage(cfg, ctx)
  File "wally/run_test.py", line 607, in load_data_from_path_stage
    for tp, vals in load_data_from_path(var_dir).items():
  File "wally/run_test.py", line 594, in load_data_from_path
    raw_res = yaml_load(open(files['raw_results']).read())
IOError: [Errno 2] No such file or directory: 'wally_results/free_mako/raw_results.yaml'
18:20:29 -    DEBUG - wally           - Start utils.cleanup
18:20:29 -     INFO - wally           - All info stored into /home/mosorio/wally/wally_results/free_mako
18:20:29 -    ERROR - wally           - Tests are failed. See detailed error above
