00:10:32 -     INFO - wally           - All info would be stored into /home/mosorio/wally/wally_results/joint_mite
00:10:32 -     INFO - wally           - Start discover_stage
00:10:32 -     INFO - wally           - Start reuse_vms_stage
00:10:32 -     INFO - wally           - Start log_nodes_statistic_stage
00:10:32 -     INFO - wally           - Found 1 nodes total
00:10:32 -    DEBUG - wally           - Found 1 nodes with role testnode
00:10:32 -     INFO - wally           - Start save_nodes_stage
00:10:32 -     INFO - wally           - Start connect_stage
00:10:32 -     INFO - wally           - Connecting to nodes
00:10:32 -     INFO - wally           - All nodes connected successfully
00:10:32 -     INFO - wally           - Start run_tests_stage
00:10:32 -    DEBUG - wally           - Run preparation
00:10:34 -    DEBUG - wally           - prefill is skipped
18:20:59 -     INFO - wally           - All info would be stored into /home/mosorio/wally/wally_results/joint_mite
18:20:59 -     INFO - wally           - Start load_data_from_path_stage
18:20:59 -    ERROR - wally           - During load_data_from_path_stage
Traceback (most recent call last):
  File "wally/main.py", line 125, in log_stage
    yield
  File "wally/main.py", line 277, in main
    stage(cfg, ctx)
  File "wally/run_test.py", line 607, in load_data_from_path_stage
    for tp, vals in load_data_from_path(var_dir).items():
  File "wally/run_test.py", line 594, in load_data_from_path
    raw_res = yaml_load(open(files['raw_results']).read())
IOError: [Errno 2] No such file or directory: 'wally_results/joint_mite/raw_results.yaml'
18:20:59 -    DEBUG - wally           - Start utils.cleanup
18:20:59 -     INFO - wally           - All info stored into /home/mosorio/wally/wally_results/joint_mite
18:20:59 -    ERROR - wally           - Tests are failed. See detailed error above
